/tmp/slurmd/job372322/slurm_script: line 13: activate: No such file or directory
Traceback (most recent call last):
  File "/net/fs06/d0/linyao/GFD_Polar_vortex/ddloutput/NL_findRe/Nphi128_Nr256_Re1.2_F400/ivp.py", line 117, in <module>
    write, initial_timestep = solver.load_state('snapshots/snapshots_s2.h5')
                              ~~~~~~~~~~~~~~~~~^^^^^^^^^^^^^^^^^^^^^^^^^^^^^
  File "/home/linyao/.conda/envs/dedalus3/lib/python3.13/site-packages/dedalus/core/solvers.py", line 654, in load_state
    with h5py.File(str(path), mode='r') as file:
         ~~~~~~~~~^^^^^^^^^^^^^^^^^^^^^
  File "/home/linyao/.conda/envs/dedalus3/lib/python3.13/site-packages/h5py/_hl/files.py", line 564, in __init__
    fid = make_fid(name, mode, userblock_size, fapl, fcpl, swmr=swmr)
  File "/home/linyao/.conda/envs/dedalus3/lib/python3.13/site-packages/h5py/_hl/files.py", line 238, in make_fid
    fid = h5f.open(name, flags, fapl=fapl)
  File "h5py/_objects.pyx", line 56, in h5py._objects.with_phil.wrapper
  File "h5py/_objects.pyx", line 57, in h5py._objects.with_phil.wrapper
  File "h5py/h5f.pyx", line 102, in h5py.h5f.open
FileNotFoundError: [Errno 2] Unable to synchronously open file (unable to open file: name = 'snapshots/snapshots_s2.h5', errno = 2, error message = 'No such file or directory', flags = 0, o_flags = 0)
Traceback (most recent call last):
  File "/net/fs06/d0/linyao/GFD_Polar_vortex/ddloutput/NL_findRe/Nphi128_Nr256_Re1.2_F400/ivp.py", line 117, in <module>
    write, initial_timestep = solver.load_state('snapshots/snapshots_s2.h5')
                              ~~~~~~~~~~~~~~~~~^^^^^^^^^^^^^^^^^^^^^^^^^^^^^
  File "/home/linyao/.conda/envs/dedalus3/lib/python3.13/site-packages/dedalus/core/solvers.py", line 654, in load_state
    with h5py.File(str(path), mode='r') as file:
         ~~~~~~~~~^^^^^^^^^^^^^^^^^^^^^
  File "/home/linyao/.conda/envs/dedalus3/lib/python3.13/site-packages/h5py/_hl/files.py", line 564, in __init__
    fid = make_fid(name, mode, userblock_size, fapl, fcpl, swmr=swmr)
  File "/home/linyao/.conda/envs/dedalus3/lib/python3.13/site-packages/h5py/_hl/files.py", line 238, in make_fid
    fid = h5f.open(name, flags, fapl=fapl)
  File "h5py/_objects.pyx", line 56, in h5py._objects.with_phil.wrapper
  File "h5py/_objects.pyx", line 57, in h5py._objects.with_phil.wrapper
  File "h5py/h5f.pyx", line 102, in h5py.h5f.open
FileNotFoundError: [Errno 2] Unable to synchronously open file (unable to open file: name = 'snapshots/snapshots_s2.h5', errno = 2, error message = 'No such file or directory', flags = 0, o_flags = 0)
Traceback (most recent call last):
  File "/net/fs06/d0/linyao/GFD_Polar_vortex/ddloutput/NL_findRe/Nphi128_Nr256_Re1.2_F400/ivp.py", line 117, in <module>
    write, initial_timestep = solver.load_state('snapshots/snapshots_s2.h5')
                              ~~~~~~~~~~~~~~~~~^^^^^^^^^^^^^^^^^^^^^^^^^^^^^
  File "/home/linyao/.conda/envs/dedalus3/lib/python3.13/site-packages/dedalus/core/solvers.py", line 654, in load_state
    with h5py.File(str(path), mode='r') as file:
         ~~~~~~~~~^^^^^^^^^^^^^^^^^^^^^
  File "/home/linyao/.conda/envs/dedalus3/lib/python3.13/site-packages/h5py/_hl/files.py", line 564, in __init__
    fid = make_fid(name, mode, userblock_size, fapl, fcpl, swmr=swmr)
  File "/home/linyao/.conda/envs/dedalus3/lib/python3.13/site-packages/h5py/_hl/files.py", line 238, in make_fid
    fid = h5f.open(name, flags, fapl=fapl)
  File "h5py/_objects.pyx", line 56, in h5py._objects.with_phil.wrapper
  File "h5py/_objects.pyx", line 57, in h5py._objects.with_phil.wrapper
  File "h5py/h5f.pyx", line 102, in h5py.h5f.open
FileNotFoundError: [Errno 2] Unable to synchronously open file (unable to open file: name = 'snapshots/snapshots_s2.h5', errno = 2, error message = 'No such file or directory', flags = 0, o_flags = 0)
Traceback (most recent call last):
  File "/net/fs06/d0/linyao/GFD_Polar_vortex/ddloutput/NL_findRe/Nphi128_Nr256_Re1.2_F400/ivp.py", line 117, in <module>
    write, initial_timestep = solver.load_state('snapshots/snapshots_s2.h5')
                              ~~~~~~~~~~~~~~~~~^^^^^^^^^^^^^^^^^^^^^^^^^^^^^
  File "/home/linyao/.conda/envs/dedalus3/lib/python3.13/site-packages/dedalus/core/solvers.py", line 654, in load_state
    with h5py.File(str(path), mode='r') as file:
         ~~~~~~~~~^^^^^^^^^^^^^^^^^^^^^
  File "/home/linyao/.conda/envs/dedalus3/lib/python3.13/site-packages/h5py/_hl/files.py", line 564, in __init__
    fid = make_fid(name, mode, userblock_size, fapl, fcpl, swmr=swmr)
  File "/home/linyao/.conda/envs/dedalus3/lib/python3.13/site-packages/h5py/_hl/files.py", line 238, in make_fid
    fid = h5f.open(name, flags, fapl=fapl)
  File "h5py/_objects.pyx", line 56, in h5py._objects.with_phil.wrapper
  File "h5py/_objects.pyx", line 57, in h5py._objects.with_phil.wrapper
  File "h5py/h5f.pyx", line 102, in h5py.h5f.open
FileNotFoundError: [Errno 2] Unable to synchronously open file (unable to open file: name = 'snapshots/snapshots_s2.h5', errno = 2, error message = 'No such file or directory', flags = 0, o_flags = 0)
Traceback (most recent call last):
  File "/net/fs06/d0/linyao/GFD_Polar_vortex/ddloutput/NL_findRe/Nphi128_Nr256_Re1.2_F400/ivp.py", line 117, in <module>
    write, initial_timestep = solver.load_state('snapshots/snapshots_s2.h5')
                              ~~~~~~~~~~~~~~~~~^^^^^^^^^^^^^^^^^^^^^^^^^^^^^
  File "/home/linyao/.conda/envs/dedalus3/lib/python3.13/site-packages/dedalus/core/solvers.py", line 654, in load_state
    with h5py.File(str(path), mode='r') as file:
         ~~~~~~~~~^^^^^^^^^^^^^^^^^^^^^
  File "/home/linyao/.conda/envs/dedalus3/lib/python3.13/site-packages/h5py/_hl/files.py", line 564, in __init__
    fid = make_fid(name, mode, userblock_size, fapl, fcpl, swmr=swmr)
  File "/home/linyao/.conda/envs/dedalus3/lib/python3.13/site-packages/h5py/_hl/files.py", line 238, in make_fid
    fid = h5f.open(name, flags, fapl=fapl)
  File "h5py/_objects.pyx", line 56, in h5py._objects.with_phil.wrapper
  File "h5py/_objects.pyx", line 57, in h5py._objects.with_phil.wrapper
  File "h5py/h5f.pyx", line 102, in h5py.h5f.open
FileNotFoundError: [Errno 2] Unable to synchronously open file (unable to open file: name = 'snapshots/snapshots_s2.h5', errno = 2, error message = 'No such file or directory', flags = 0, o_flags = 0)
Traceback (most recent call last):
  File "/net/fs06/d0/linyao/GFD_Polar_vortex/ddloutput/NL_findRe/Nphi128_Nr256_Re1.2_F400/ivp.py", line 117, in <module>
    write, initial_timestep = solver.load_state('snapshots/snapshots_s2.h5')
                              ~~~~~~~~~~~~~~~~~^^^^^^^^^^^^^^^^^^^^^^^^^^^^^
  File "/home/linyao/.conda/envs/dedalus3/lib/python3.13/site-packages/dedalus/core/solvers.py", line 654, in load_state
    with h5py.File(str(path), mode='r') as file:
         ~~~~~~~~~^^^^^^^^^^^^^^^^^^^^^
  File "/home/linyao/.conda/envs/dedalus3/lib/python3.13/site-packages/h5py/_hl/files.py", line 564, in __init__
    fid = make_fid(name, mode, userblock_size, fapl, fcpl, swmr=swmr)
  File "/home/linyao/.conda/envs/dedalus3/lib/python3.13/site-packages/h5py/_hl/files.py", line 238, in make_fid
    fid = h5f.open(name, flags, fapl=fapl)
  File "h5py/_objects.pyx", line 56, in h5py._objects.with_phil.wrapper
  File "h5py/_objects.pyx", line 57, in h5py._objects.with_phil.wrapper
  File "h5py/h5f.pyx", line 102, in h5py.h5f.open
FileNotFoundError: [Errno 2] Unable to synchronously open file (unable to open file: name = 'snapshots/snapshots_s2.h5', errno = 2, error message = 'No such file or directory', flags = 0, o_flags = 0)
Traceback (most recent call last):
  File "/net/fs06/d0/linyao/GFD_Polar_vortex/ddloutput/NL_findRe/Nphi128_Nr256_Re1.2_F400/ivp.py", line 117, in <module>
    write, initial_timestep = solver.load_state('snapshots/snapshots_s2.h5')
                              ~~~~~~~~~~~~~~~~~^^^^^^^^^^^^^^^^^^^^^^^^^^^^^
  File "/home/linyao/.conda/envs/dedalus3/lib/python3.13/site-packages/dedalus/core/solvers.py", line 654, in load_state
    with h5py.File(str(path), mode='r') as file:
         ~~~~~~~~~^^^^^^^^^^^^^^^^^^^^^
  File "/home/linyao/.conda/envs/dedalus3/lib/python3.13/site-packages/h5py/_hl/files.py", line 564, in __init__
    fid = make_fid(name, mode, userblock_size, fapl, fcpl, swmr=swmr)
  File "/home/linyao/.conda/envs/dedalus3/lib/python3.13/site-packages/h5py/_hl/files.py", line 238, in make_fid
    fid = h5f.open(name, flags, fapl=fapl)
  File "h5py/_objects.pyx", line 56, in h5py._objects.with_phil.wrapper
  File "h5py/_objects.pyx", line 57, in h5py._objects.with_phil.wrapper
  File "h5py/h5f.pyx", line 102, in h5py.h5f.open
FileNotFoundError: [Errno 2] Unable to synchronously open file (unable to open file: name = 'snapshots/snapshots_s2.h5', errno = 2, error message = 'No such file or directory', flags = 0, o_flags = 0)
Traceback (most recent call last):
Traceback (most recent call last):
  File "/net/fs06/d0/linyao/GFD_Polar_vortex/ddloutput/NL_findRe/Nphi128_Nr256_Re1.2_F400/ivp.py", line 117, in <module>
    write, initial_timestep = solver.load_state('snapshots/snapshots_s2.h5')
                              ~~~~~~~~~~~~~~~~~^^^^^^^^^^^^^^^^^^^^^^^^^^^^^
  File "/net/fs06/d0/linyao/GFD_Polar_vortex/ddloutput/NL_findRe/Nphi128_Nr256_Re1.2_F400/ivp.py", line 117, in <module>
    write, initial_timestep = solver.load_state('snapshots/snapshots_s2.h5')
                              ~~~~~~~~~~~~~~~~~^^^^^^^^^^^^^^^^^^^^^^^^^^^^^
  File "/home/linyao/.conda/envs/dedalus3/lib/python3.13/site-packages/dedalus/core/solvers.py", line 654, in load_state
    with h5py.File(str(path), mode='r') as file:
         ~~~~~~~~~^^^^^^^^^^^^^^^^^^^^^
  File "/home/linyao/.conda/envs/dedalus3/lib/python3.13/site-packages/h5py/_hl/files.py", line 564, in __init__
    fid = make_fid(name, mode, userblock_size, fapl, fcpl, swmr=swmr)
  File "/home/linyao/.conda/envs/dedalus3/lib/python3.13/site-packages/h5py/_hl/files.py", line 238, in make_fid
    fid = h5f.open(name, flags, fapl=fapl)
  File "h5py/_objects.pyx", line 56, in h5py._objects.with_phil.wrapper
  File "h5py/_objects.pyx", line 57, in h5py._objects.with_phil.wrapper
  File "h5py/h5f.pyx", line 102, in h5py.h5f.open
FileNotFoundError: [Errno 2] Unable to synchronously open file (unable to open file: name = 'snapshots/snapshots_s2.h5', errno = 2, error message = 'No such file or directory', flags = 0, o_flags = 0)
  File "/home/linyao/.conda/envs/dedalus3/lib/python3.13/site-packages/dedalus/core/solvers.py", line 654, in load_state
    with h5py.File(str(path), mode='r') as file:
         ~~~~~~~~~^^^^^^^^^^^^^^^^^^^^^
  File "/home/linyao/.conda/envs/dedalus3/lib/python3.13/site-packages/h5py/_hl/files.py", line 564, in __init__
    fid = make_fid(name, mode, userblock_size, fapl, fcpl, swmr=swmr)
  File "/home/linyao/.conda/envs/dedalus3/lib/python3.13/site-packages/h5py/_hl/files.py", line 238, in make_fid
    fid = h5f.open(name, flags, fapl=fapl)
  File "h5py/_objects.pyx", line 56, in h5py._objects.with_phil.wrapper
  File "h5py/_objects.pyx", line 57, in h5py._objects.with_phil.wrapper
  File "h5py/h5f.pyx", line 102, in h5py.h5f.open
FileNotFoundError: [Errno 2] Unable to synchronously open file (unable to open file: name = 'snapshots/snapshots_s2.h5', errno = 2, error message = 'No such file or directory', flags = 0, o_flags = 0)
Traceback (most recent call last):
  File "/net/fs06/d0/linyao/GFD_Polar_vortex/ddloutput/NL_findRe/Nphi128_Nr256_Re1.2_F400/ivp.py", line 117, in <module>
    write, initial_timestep = solver.load_state('snapshots/snapshots_s2.h5')
                              ~~~~~~~~~~~~~~~~~^^^^^^^^^^^^^^^^^^^^^^^^^^^^^
  File "/home/linyao/.conda/envs/dedalus3/lib/python3.13/site-packages/dedalus/core/solvers.py", line 654, in load_state
    with h5py.File(str(path), mode='r') as file:
         ~~~~~~~~~^^^^^^^^^^^^^^^^^^^^^
  File "/home/linyao/.conda/envs/dedalus3/lib/python3.13/site-packages/h5py/_hl/files.py", line 564, in __init__
    fid = make_fid(name, mode, userblock_size, fapl, fcpl, swmr=swmr)
  File "/home/linyao/.conda/envs/dedalus3/lib/python3.13/site-packages/h5py/_hl/files.py", line 238, in make_fid
    fid = h5f.open(name, flags, fapl=fapl)
  File "h5py/_objects.pyx", line 56, in h5py._objects.with_phil.wrapper
  File "h5py/_objects.pyx", line 57, in h5py._objects.with_phil.wrapper
  File "h5py/h5f.pyx", line 102, in h5py.h5f.open
FileNotFoundError: [Errno 2] Unable to synchronously open file (unable to open file: name = 'snapshots/snapshots_s2.h5', errno = 2, error message = 'No such file or directory', flags = 0, o_flags = 0)
Traceback (most recent call last):
  File "/net/fs06/d0/linyao/GFD_Polar_vortex/ddloutput/NL_findRe/Nphi128_Nr256_Re1.2_F400/ivp.py", line 117, in <module>
    write, initial_timestep = solver.load_state('snapshots/snapshots_s2.h5')
                              ~~~~~~~~~~~~~~~~~^^^^^^^^^^^^^^^^^^^^^^^^^^^^^
  File "/home/linyao/.conda/envs/dedalus3/lib/python3.13/site-packages/dedalus/core/solvers.py", line 654, in load_state
    with h5py.File(str(path), mode='r') as file:
         ~~~~~~~~~^^^^^^^^^^^^^^^^^^^^^
  File "/home/linyao/.conda/envs/dedalus3/lib/python3.13/site-packages/h5py/_hl/files.py", line 564, in __init__
    fid = make_fid(name, mode, userblock_size, fapl, fcpl, swmr=swmr)
  File "/home/linyao/.conda/envs/dedalus3/lib/python3.13/site-packages/h5py/_hl/files.py", line 238, in make_fid
    fid = h5f.open(name, flags, fapl=fapl)
  File "h5py/_objects.pyx", line 56, in h5py._objects.with_phil.wrapper
  File "h5py/_objects.pyx", line 57, in h5py._objects.with_phil.wrapper
  File "h5py/h5f.pyx", line 102, in h5py.h5f.open
FileNotFoundError: [Errno 2] Unable to synchronously open file (unable to open file: name = 'snapshots/snapshots_s2.h5', errno = 2, error message = 'No such file or directory', flags = 0, o_flags = 0)
Traceback (most recent call last):
  File "/net/fs06/d0/linyao/GFD_Polar_vortex/ddloutput/NL_findRe/Nphi128_Nr256_Re1.2_F400/ivp.py", line 117, in <module>
    write, initial_timestep = solver.load_state('snapshots/snapshots_s2.h5')
                              ~~~~~~~~~~~~~~~~~^^^^^^^^^^^^^^^^^^^^^^^^^^^^^
  File "/home/linyao/.conda/envs/dedalus3/lib/python3.13/site-packages/dedalus/core/solvers.py", line 654, in load_state
    with h5py.File(str(path), mode='r') as file:
         ~~~~~~~~~^^^^^^^^^^^^^^^^^^^^^
  File "/home/linyao/.conda/envs/dedalus3/lib/python3.13/site-packages/h5py/_hl/files.py", line 564, in __init__
    fid = make_fid(name, mode, userblock_size, fapl, fcpl, swmr=swmr)
  File "/home/linyao/.conda/envs/dedalus3/lib/python3.13/site-packages/h5py/_hl/files.py", line 238, in make_fid
    fid = h5f.open(name, flags, fapl=fapl)
  File "h5py/_objects.pyx", line 56, in h5py._objects.with_phil.wrapper
  File "h5py/_objects.pyx", line 57, in h5py._objects.with_phil.wrapper
  File "h5py/h5f.pyx", line 102, in h5py.h5f.open
FileNotFoundError: [Errno 2] Unable to synchronously open file (unable to open file: name = 'snapshots/snapshots_s2.h5', errno = 2, error message = 'No such file or directory', flags = 0, o_flags = 0)
Traceback (most recent call last):
  File "/net/fs06/d0/linyao/GFD_Polar_vortex/ddloutput/NL_findRe/Nphi128_Nr256_Re1.2_F400/ivp.py", line 117, in <module>
    write, initial_timestep = solver.load_state('snapshots/snapshots_s2.h5')
                              ~~~~~~~~~~~~~~~~~^^^^^^^^^^^^^^^^^^^^^^^^^^^^^
  File "/home/linyao/.conda/envs/dedalus3/lib/python3.13/site-packages/dedalus/core/solvers.py", line 654, in load_state
    with h5py.File(str(path), mode='r') as file:
         ~~~~~~~~~^^^^^^^^^^^^^^^^^^^^^
  File "/home/linyao/.conda/envs/dedalus3/lib/python3.13/site-packages/h5py/_hl/files.py", line 564, in __init__
    fid = make_fid(name, mode, userblock_size, fapl, fcpl, swmr=swmr)
  File "/home/linyao/.conda/envs/dedalus3/lib/python3.13/site-packages/h5py/_hl/files.py", line 238, in make_fid
    fid = h5f.open(name, flags, fapl=fapl)
  File "h5py/_objects.pyx", line 56, in h5py._objects.with_phil.wrapper
  File "h5py/_objects.pyx", line 57, in h5py._objects.with_phil.wrapper
  File "h5py/h5f.pyx", line 102, in h5py.h5f.open
FileNotFoundError: [Errno 2] Unable to synchronously open file (unable to open file: name = 'snapshots/snapshots_s2.h5', errno = 2, error message = 'No such file or directory', flags = 0, o_flags = 0)
Traceback (most recent call last):
  File "/net/fs06/d0/linyao/GFD_Polar_vortex/ddloutput/NL_findRe/Nphi128_Nr256_Re1.2_F400/ivp.py", line 117, in <module>
    write, initial_timestep = solver.load_state('snapshots/snapshots_s2.h5')
                              ~~~~~~~~~~~~~~~~~^^^^^^^^^^^^^^^^^^^^^^^^^^^^^
  File "/home/linyao/.conda/envs/dedalus3/lib/python3.13/site-packages/dedalus/core/solvers.py", line 654, in load_state
    with h5py.File(str(path), mode='r') as file:
         ~~~~~~~~~^^^^^^^^^^^^^^^^^^^^^
  File "/home/linyao/.conda/envs/dedalus3/lib/python3.13/site-packages/h5py/_hl/files.py", line 564, in __init__
    fid = make_fid(name, mode, userblock_size, fapl, fcpl, swmr=swmr)
  File "/home/linyao/.conda/envs/dedalus3/lib/python3.13/site-packages/h5py/_hl/files.py", line 238, in make_fid
    fid = h5f.open(name, flags, fapl=fapl)
  File "h5py/_objects.pyx", line 56, in h5py._objects.with_phil.wrapper
  File "h5py/_objects.pyx", line 57, in h5py._objects.with_phil.wrapper
  File "h5py/h5f.pyx", line 102, in h5py.h5f.open
FileNotFoundError: [Errno 2] Unable to synchronously open file (unable to open file: name = 'snapshots/snapshots_s2.h5', errno = 2, error message = 'No such file or directory', flags = 0, o_flags = 0)
Traceback (most recent call last):
  File "/net/fs06/d0/linyao/GFD_Polar_vortex/ddloutput/NL_findRe/Nphi128_Nr256_Re1.2_F400/ivp.py", line 117, in <module>
    write, initial_timestep = solver.load_state('snapshots/snapshots_s2.h5')
                              ~~~~~~~~~~~~~~~~~^^^^^^^^^^^^^^^^^^^^^^^^^^^^^
  File "/home/linyao/.conda/envs/dedalus3/lib/python3.13/site-packages/dedalus/core/solvers.py", line 654, in load_state
    with h5py.File(str(path), mode='r') as file:
         ~~~~~~~~~^^^^^^^^^^^^^^^^^^^^^
  File "/home/linyao/.conda/envs/dedalus3/lib/python3.13/site-packages/h5py/_hl/files.py", line 564, in __init__
    fid = make_fid(name, mode, userblock_size, fapl, fcpl, swmr=swmr)
  File "/home/linyao/.conda/envs/dedalus3/lib/python3.13/site-packages/h5py/_hl/files.py", line 238, in make_fid
    fid = h5f.open(name, flags, fapl=fapl)
  File "h5py/_objects.pyx", line 56, in h5py._objects.with_phil.wrapper
  File "h5py/_objects.pyx", line 57, in h5py._objects.with_phil.wrapper
  File "h5py/h5f.pyx", line 102, in h5py.h5f.open
FileNotFoundError: [Errno 2] Unable to synchronously open file (unable to open file: name = 'snapshots/snapshots_s2.h5', errno = 2, error message = 'No such file or directory', flags = 0, o_flags = 0)
Traceback (most recent call last):
  File "/net/fs06/d0/linyao/GFD_Polar_vortex/ddloutput/NL_findRe/Nphi128_Nr256_Re1.2_F400/ivp.py", line 117, in <module>
    write, initial_timestep = solver.load_state('snapshots/snapshots_s2.h5')
                              ~~~~~~~~~~~~~~~~~^^^^^^^^^^^^^^^^^^^^^^^^^^^^^
  File "/home/linyao/.conda/envs/dedalus3/lib/python3.13/site-packages/dedalus/core/solvers.py", line 654, in load_state
    with h5py.File(str(path), mode='r') as file:
         ~~~~~~~~~^^^^^^^^^^^^^^^^^^^^^
  File "/home/linyao/.conda/envs/dedalus3/lib/python3.13/site-packages/h5py/_hl/files.py", line 564, in __init__
    fid = make_fid(name, mode, userblock_size, fapl, fcpl, swmr=swmr)
  File "/home/linyao/.conda/envs/dedalus3/lib/python3.13/site-packages/h5py/_hl/files.py", line 238, in make_fid
    fid = h5f.open(name, flags, fapl=fapl)
  File "h5py/_objects.pyx", line 56, in h5py._objects.with_phil.wrapper
  File "h5py/_objects.pyx", line 57, in h5py._objects.with_phil.wrapper
  File "h5py/h5f.pyx", line 102, in h5py.h5f.open
FileNotFoundError: [Errno 2] Unable to synchronously open file (unable to open file: name = 'snapshots/snapshots_s2.h5', errno = 2, error message = 'No such file or directory', flags = 0, o_flags = 0)
Traceback (most recent call last):
  File "/net/fs06/d0/linyao/GFD_Polar_vortex/ddloutput/NL_findRe/Nphi128_Nr256_Re1.2_F400/ivp.py", line 117, in <module>
    write, initial_timestep = solver.load_state('snapshots/snapshots_s2.h5')
                              ~~~~~~~~~~~~~~~~~^^^^^^^^^^^^^^^^^^^^^^^^^^^^^
  File "/home/linyao/.conda/envs/dedalus3/lib/python3.13/site-packages/dedalus/core/solvers.py", line 654, in load_state
    with h5py.File(str(path), mode='r') as file:
         ~~~~~~~~~^^^^^^^^^^^^^^^^^^^^^
  File "/home/linyao/.conda/envs/dedalus3/lib/python3.13/site-packages/h5py/_hl/files.py", line 564, in __init__
    fid = make_fid(name, mode, userblock_size, fapl, fcpl, swmr=swmr)
  File "/home/linyao/.conda/envs/dedalus3/lib/python3.13/site-packages/h5py/_hl/files.py", line 238, in make_fid
    fid = h5f.open(name, flags, fapl=fapl)
  File "h5py/_objects.pyx", line 56, in h5py._objects.with_phil.wrapper
  File "h5py/_objects.pyx", line 57, in h5py._objects.with_phil.wrapper
  File "h5py/h5f.pyx", line 102, in h5py.h5f.open
FileNotFoundError: [Errno 2] Unable to synchronously open file (unable to open file: name = 'snapshots/snapshots_s2.h5', errno = 2, error message = 'No such file or directory', flags = 0, o_flags = 0)
Traceback (most recent call last):
  File "/net/fs06/d0/linyao/GFD_Polar_vortex/ddloutput/NL_findRe/Nphi128_Nr256_Re1.2_F400/ivp.py", line 117, in <module>
    write, initial_timestep = solver.load_state('snapshots/snapshots_s2.h5')
                              ~~~~~~~~~~~~~~~~~^^^^^^^^^^^^^^^^^^^^^^^^^^^^^
  File "/home/linyao/.conda/envs/dedalus3/lib/python3.13/site-packages/dedalus/core/solvers.py", line 654, in load_state
    with h5py.File(str(path), mode='r') as file:
         ~~~~~~~~~^^^^^^^^^^^^^^^^^^^^^
  File "/home/linyao/.conda/envs/dedalus3/lib/python3.13/site-packages/h5py/_hl/files.py", line 564, in __init__
    fid = make_fid(name, mode, userblock_size, fapl, fcpl, swmr=swmr)
  File "/home/linyao/.conda/envs/dedalus3/lib/python3.13/site-packages/h5py/_hl/files.py", line 238, in make_fid
    fid = h5f.open(name, flags, fapl=fapl)
  File "h5py/_objects.pyx", line 56, in h5py._objects.with_phil.wrapper
  File "h5py/_objects.pyx", line 57, in h5py._objects.with_phil.wrapper
  File "h5py/h5f.pyx", line 102, in h5py.h5f.open
FileNotFoundError: [Errno 2] Unable to synchronously open file (unable to open file: name = 'snapshots/snapshots_s2.h5', errno = 2, error message = 'No such file or directory', flags = 0, o_flags = 0)
Traceback (most recent call last):
  File "/net/fs06/d0/linyao/GFD_Polar_vortex/ddloutput/NL_findRe/Nphi128_Nr256_Re1.2_F400/ivp.py", line 117, in <module>
    write, initial_timestep = solver.load_state('snapshots/snapshots_s2.h5')
                              ~~~~~~~~~~~~~~~~~^^^^^^^^^^^^^^^^^^^^^^^^^^^^^
  File "/home/linyao/.conda/envs/dedalus3/lib/python3.13/site-packages/dedalus/core/solvers.py", line 654, in load_state
    with h5py.File(str(path), mode='r') as file:
         ~~~~~~~~~^^^^^^^^^^^^^^^^^^^^^
  File "/home/linyao/.conda/envs/dedalus3/lib/python3.13/site-packages/h5py/_hl/files.py", line 564, in __init__
    fid = make_fid(name, mode, userblock_size, fapl, fcpl, swmr=swmr)
  File "/home/linyao/.conda/envs/dedalus3/lib/python3.13/site-packages/h5py/_hl/files.py", line 238, in make_fid
    fid = h5f.open(name, flags, fapl=fapl)
  File "h5py/_objects.pyx", line 56, in h5py._objects.with_phil.wrapper
  File "h5py/_objects.pyx", line 57, in h5py._objects.with_phil.wrapper
  File "h5py/h5f.pyx", line 102, in h5py.h5f.open
FileNotFoundError: [Errno 2] Unable to synchronously open file (unable to open file: name = 'snapshots/snapshots_s2.h5', errno = 2, error message = 'No such file or directory', flags = 0, o_flags = 0)
Traceback (most recent call last):
  File "/net/fs06/d0/linyao/GFD_Polar_vortex/ddloutput/NL_findRe/Nphi128_Nr256_Re1.2_F400/ivp.py", line 117, in <module>
    write, initial_timestep = solver.load_state('snapshots/snapshots_s2.h5')
                              ~~~~~~~~~~~~~~~~~^^^^^^^^^^^^^^^^^^^^^^^^^^^^^
  File "/home/linyao/.conda/envs/dedalus3/lib/python3.13/site-packages/dedalus/core/solvers.py", line 654, in load_state
    with h5py.File(str(path), mode='r') as file:
         ~~~~~~~~~^^^^^^^^^^^^^^^^^^^^^
  File "/home/linyao/.conda/envs/dedalus3/lib/python3.13/site-packages/h5py/_hl/files.py", line 564, in __init__
    fid = make_fid(name, mode, userblock_size, fapl, fcpl, swmr=swmr)
  File "/home/linyao/.conda/envs/dedalus3/lib/python3.13/site-packages/h5py/_hl/files.py", line 238, in make_fid
    fid = h5f.open(name, flags, fapl=fapl)
  File "h5py/_objects.pyx", line 56, in h5py._objects.with_phil.wrapper
  File "h5py/_objects.pyx", line 57, in h5py._objects.with_phil.wrapper
  File "h5py/h5f.pyx", line 102, in h5py.h5f.open
FileNotFoundError: [Errno 2] Unable to synchronously open file (unable to open file: name = 'snapshots/snapshots_s2.h5', errno = 2, error message = 'No such file or directory', flags = 0, o_flags = 0)
Traceback (most recent call last):
  File "/net/fs06/d0/linyao/GFD_Polar_vortex/ddloutput/NL_findRe/Nphi128_Nr256_Re1.2_F400/ivp.py", line 117, in <module>
    write, initial_timestep = solver.load_state('snapshots/snapshots_s2.h5')
                              ~~~~~~~~~~~~~~~~~^^^^^^^^^^^^^^^^^^^^^^^^^^^^^
  File "/home/linyao/.conda/envs/dedalus3/lib/python3.13/site-packages/dedalus/core/solvers.py", line 654, in load_state
    with h5py.File(str(path), mode='r') as file:
         ~~~~~~~~~^^^^^^^^^^^^^^^^^^^^^
  File "/home/linyao/.conda/envs/dedalus3/lib/python3.13/site-packages/h5py/_hl/files.py", line 564, in __init__
    fid = make_fid(name, mode, userblock_size, fapl, fcpl, swmr=swmr)
  File "/home/linyao/.conda/envs/dedalus3/lib/python3.13/site-packages/h5py/_hl/files.py", line 238, in make_fid
    fid = h5f.open(name, flags, fapl=fapl)
  File "h5py/_objects.pyx", line 56, in h5py._objects.with_phil.wrapper
  File "h5py/_objects.pyx", line 57, in h5py._objects.with_phil.wrapper
  File "h5py/h5f.pyx", line 102, in h5py.h5f.open
FileNotFoundError: [Errno 2] Unable to synchronously open file (unable to open file: name = 'snapshots/snapshots_s2.h5', errno = 2, error message = 'No such file or directory', flags = 0, o_flags = 0)
Traceback (most recent call last):
  File "/net/fs06/d0/linyao/GFD_Polar_vortex/ddloutput/NL_findRe/Nphi128_Nr256_Re1.2_F400/ivp.py", line 117, in <module>
    write, initial_timestep = solver.load_state('snapshots/snapshots_s2.h5')
                              ~~~~~~~~~~~~~~~~~^^^^^^^^^^^^^^^^^^^^^^^^^^^^^
  File "/home/linyao/.conda/envs/dedalus3/lib/python3.13/site-packages/dedalus/core/solvers.py", line 654, in load_state
    with h5py.File(str(path), mode='r') as file:
         ~~~~~~~~~^^^^^^^^^^^^^^^^^^^^^
  File "/home/linyao/.conda/envs/dedalus3/lib/python3.13/site-packages/h5py/_hl/files.py", line 564, in __init__
    fid = make_fid(name, mode, userblock_size, fapl, fcpl, swmr=swmr)
  File "/home/linyao/.conda/envs/dedalus3/lib/python3.13/site-packages/h5py/_hl/files.py", line 238, in make_fid
    fid = h5f.open(name, flags, fapl=fapl)
  File "h5py/_objects.pyx", line 56, in h5py._objects.with_phil.wrapper
  File "h5py/_objects.pyx", line 57, in h5py._objects.with_phil.wrapper
  File "h5py/h5f.pyx", line 102, in h5py.h5f.open
FileNotFoundError: [Errno 2] Unable to synchronously open file (unable to open file: name = 'snapshots/snapshots_s2.h5', errno = 2, error message = 'No such file or directory', flags = 0, o_flags = 0)
Traceback (most recent call last):
  File "/net/fs06/d0/linyao/GFD_Polar_vortex/ddloutput/NL_findRe/Nphi128_Nr256_Re1.2_F400/ivp.py", line 117, in <module>
    write, initial_timestep = solver.load_state('snapshots/snapshots_s2.h5')
                              ~~~~~~~~~~~~~~~~~^^^^^^^^^^^^^^^^^^^^^^^^^^^^^
  File "/home/linyao/.conda/envs/dedalus3/lib/python3.13/site-packages/dedalus/core/solvers.py", line 654, in load_state
    with h5py.File(str(path), mode='r') as file:
         ~~~~~~~~~^^^^^^^^^^^^^^^^^^^^^
  File "/home/linyao/.conda/envs/dedalus3/lib/python3.13/site-packages/h5py/_hl/files.py", line 564, in __init__
    fid = make_fid(name, mode, userblock_size, fapl, fcpl, swmr=swmr)
  File "/home/linyao/.conda/envs/dedalus3/lib/python3.13/site-packages/h5py/_hl/files.py", line 238, in make_fid
    fid = h5f.open(name, flags, fapl=fapl)
  File "h5py/_objects.pyx", line 56, in h5py._objects.with_phil.wrapper
  File "h5py/_objects.pyx", line 57, in h5py._objects.with_phil.wrapper
  File "h5py/h5f.pyx", line 102, in h5py.h5f.open
FileNotFoundError: [Errno 2] Unable to synchronously open file (unable to open file: name = 'snapshots/snapshots_s2.h5', errno = 2, error message = 'No such file or directory', flags = 0, o_flags = 0)
Traceback (most recent call last):
  File "/net/fs06/d0/linyao/GFD_Polar_vortex/ddloutput/NL_findRe/Nphi128_Nr256_Re1.2_F400/ivp.py", line 117, in <module>
    write, initial_timestep = solver.load_state('snapshots/snapshots_s2.h5')
                              ~~~~~~~~~~~~~~~~~^^^^^^^^^^^^^^^^^^^^^^^^^^^^^
  File "/home/linyao/.conda/envs/dedalus3/lib/python3.13/site-packages/dedalus/core/solvers.py", line 654, in load_state
    with h5py.File(str(path), mode='r') as file:
         ~~~~~~~~~^^^^^^^^^^^^^^^^^^^^^
  File "/home/linyao/.conda/envs/dedalus3/lib/python3.13/site-packages/h5py/_hl/files.py", line 564, in __init__
    fid = make_fid(name, mode, userblock_size, fapl, fcpl, swmr=swmr)
  File "/home/linyao/.conda/envs/dedalus3/lib/python3.13/site-packages/h5py/_hl/files.py", line 238, in make_fid
    fid = h5f.open(name, flags, fapl=fapl)
  File "h5py/_objects.pyx", line 56, in h5py._objects.with_phil.wrapper
  File "h5py/_objects.pyx", line 57, in h5py._objects.with_phil.wrapper
  File "h5py/h5f.pyx", line 102, in h5py.h5f.open
FileNotFoundError: [Errno 2] Unable to synchronously open file (unable to open file: name = 'snapshots/snapshots_s2.h5', errno = 2, error message = 'No such file or directory', flags = 0, o_flags = 0)
Traceback (most recent call last):
  File "/net/fs06/d0/linyao/GFD_Polar_vortex/ddloutput/NL_findRe/Nphi128_Nr256_Re1.2_F400/ivp.py", line 117, in <module>
    write, initial_timestep = solver.load_state('snapshots/snapshots_s2.h5')
                              ~~~~~~~~~~~~~~~~~^^^^^^^^^^^^^^^^^^^^^^^^^^^^^
  File "/home/linyao/.conda/envs/dedalus3/lib/python3.13/site-packages/dedalus/core/solvers.py", line 654, in load_state
    with h5py.File(str(path), mode='r') as file:
         ~~~~~~~~~^^^^^^^^^^^^^^^^^^^^^
  File "/home/linyao/.conda/envs/dedalus3/lib/python3.13/site-packages/h5py/_hl/files.py", line 564, in __init__
    fid = make_fid(name, mode, userblock_size, fapl, fcpl, swmr=swmr)
  File "/home/linyao/.conda/envs/dedalus3/lib/python3.13/site-packages/h5py/_hl/files.py", line 238, in make_fid
    fid = h5f.open(name, flags, fapl=fapl)
  File "h5py/_objects.pyx", line 56, in h5py._objects.with_phil.wrapper
  File "h5py/_objects.pyx", line 57, in h5py._objects.with_phil.wrapper
  File "h5py/h5f.pyx", line 102, in h5py.h5f.open
FileNotFoundError: [Errno 2] Unable to synchronously open file (unable to open file: name = 'snapshots/snapshots_s2.h5', errno = 2, error message = 'No such file or directory', flags = 0, o_flags = 0)
Traceback (most recent call last):
  File "/net/fs06/d0/linyao/GFD_Polar_vortex/ddloutput/NL_findRe/Nphi128_Nr256_Re1.2_F400/ivp.py", line 117, in <module>
    write, initial_timestep = solver.load_state('snapshots/snapshots_s2.h5')
                              ~~~~~~~~~~~~~~~~~^^^^^^^^^^^^^^^^^^^^^^^^^^^^^
  File "/home/linyao/.conda/envs/dedalus3/lib/python3.13/site-packages/dedalus/core/solvers.py", line 654, in load_state
    with h5py.File(str(path), mode='r') as file:
         ~~~~~~~~~^^^^^^^^^^^^^^^^^^^^^
  File "/home/linyao/.conda/envs/dedalus3/lib/python3.13/site-packages/h5py/_hl/files.py", line 564, in __init__
    fid = make_fid(name, mode, userblock_size, fapl, fcpl, swmr=swmr)
  File "/home/linyao/.conda/envs/dedalus3/lib/python3.13/site-packages/h5py/_hl/files.py", line 238, in make_fid
    fid = h5f.open(name, flags, fapl=fapl)
  File "h5py/_objects.pyx", line 56, in h5py._objects.with_phil.wrapper
  File "h5py/_objects.pyx", line 57, in h5py._objects.with_phil.wrapper
  File "h5py/h5f.pyx", line 102, in h5py.h5f.open
FileNotFoundError: [Errno 2] Unable to synchronously open file (unable to open file: name = 'snapshots/snapshots_s2.h5', errno = 2, error message = 'No such file or directory', flags = 0, o_flags = 0)
Traceback (most recent call last):
  File "/net/fs06/d0/linyao/GFD_Polar_vortex/ddloutput/NL_findRe/Nphi128_Nr256_Re1.2_F400/ivp.py", line 117, in <module>
    write, initial_timestep = solver.load_state('snapshots/snapshots_s2.h5')
                              ~~~~~~~~~~~~~~~~~^^^^^^^^^^^^^^^^^^^^^^^^^^^^^
  File "/home/linyao/.conda/envs/dedalus3/lib/python3.13/site-packages/dedalus/core/solvers.py", line 654, in load_state
    with h5py.File(str(path), mode='r') as file:
         ~~~~~~~~~^^^^^^^^^^^^^^^^^^^^^
  File "/home/linyao/.conda/envs/dedalus3/lib/python3.13/site-packages/h5py/_hl/files.py", line 564, in __init__
    fid = make_fid(name, mode, userblock_size, fapl, fcpl, swmr=swmr)
  File "/home/linyao/.conda/envs/dedalus3/lib/python3.13/site-packages/h5py/_hl/files.py", line 238, in make_fid
    fid = h5f.open(name, flags, fapl=fapl)
  File "h5py/_objects.pyx", line 56, in h5py._objects.with_phil.wrapper
  File "h5py/_objects.pyx", line 57, in h5py._objects.with_phil.wrapper
  File "h5py/h5f.pyx", line 102, in h5py.h5f.open
FileNotFoundError: [Errno 2] Unable to synchronously open file (unable to open file: name = 'snapshots/snapshots_s2.h5', errno = 2, error message = 'No such file or directory', flags = 0, o_flags = 0)
Traceback (most recent call last):
  File "/net/fs06/d0/linyao/GFD_Polar_vortex/ddloutput/NL_findRe/Nphi128_Nr256_Re1.2_F400/ivp.py", line 117, in <module>
    write, initial_timestep = solver.load_state('snapshots/snapshots_s2.h5')
                              ~~~~~~~~~~~~~~~~~^^^^^^^^^^^^^^^^^^^^^^^^^^^^^
  File "/home/linyao/.conda/envs/dedalus3/lib/python3.13/site-packages/dedalus/core/solvers.py", line 654, in load_state
    with h5py.File(str(path), mode='r') as file:
         ~~~~~~~~~^^^^^^^^^^^^^^^^^^^^^
  File "/home/linyao/.conda/envs/dedalus3/lib/python3.13/site-packages/h5py/_hl/files.py", line 564, in __init__
    fid = make_fid(name, mode, userblock_size, fapl, fcpl, swmr=swmr)
  File "/home/linyao/.conda/envs/dedalus3/lib/python3.13/site-packages/h5py/_hl/files.py", line 238, in make_fid
    fid = h5f.open(name, flags, fapl=fapl)
  File "h5py/_objects.pyx", line 56, in h5py._objects.with_phil.wrapper
  File "h5py/_objects.pyx", line 57, in h5py._objects.with_phil.wrapper
  File "h5py/h5f.pyx", line 102, in h5py.h5f.open
FileNotFoundError: [Errno 2] Unable to synchronously open file (unable to open file: name = 'snapshots/snapshots_s2.h5', errno = 2, error message = 'No such file or directory', flags = 0, o_flags = 0)
Traceback (most recent call last):
  File "/net/fs06/d0/linyao/GFD_Polar_vortex/ddloutput/NL_findRe/Nphi128_Nr256_Re1.2_F400/ivp.py", line 117, in <module>
    write, initial_timestep = solver.load_state('snapshots/snapshots_s2.h5')
                              ~~~~~~~~~~~~~~~~~^^^^^^^^^^^^^^^^^^^^^^^^^^^^^
  File "/home/linyao/.conda/envs/dedalus3/lib/python3.13/site-packages/dedalus/core/solvers.py", line 654, in load_state
    with h5py.File(str(path), mode='r') as file:
         ~~~~~~~~~^^^^^^^^^^^^^^^^^^^^^
  File "/home/linyao/.conda/envs/dedalus3/lib/python3.13/site-packages/h5py/_hl/files.py", line 564, in __init__
    fid = make_fid(name, mode, userblock_size, fapl, fcpl, swmr=swmr)
  File "/home/linyao/.conda/envs/dedalus3/lib/python3.13/site-packages/h5py/_hl/files.py", line 238, in make_fid
    fid = h5f.open(name, flags, fapl=fapl)
  File "h5py/_objects.pyx", line 56, in h5py._objects.with_phil.wrapper
  File "h5py/_objects.pyx", line 57, in h5py._objects.with_phil.wrapper
  File "h5py/h5f.pyx", line 102, in h5py.h5f.open
FileNotFoundError: [Errno 2] Unable to synchronously open file (unable to open file: name = 'snapshots/snapshots_s2.h5', errno = 2, error message = 'No such file or directory', flags = 0, o_flags = 0)
Traceback (most recent call last):
Traceback (most recent call last):
  File "/net/fs06/d0/linyao/GFD_Polar_vortex/ddloutput/NL_findRe/Nphi128_Nr256_Re1.2_F400/ivp.py", line 117, in <module>
    write, initial_timestep = solver.load_state('snapshots/snapshots_s2.h5')
                              ~~~~~~~~~~~~~~~~~^^^^^^^^^^^^^^^^^^^^^^^^^^^^^
  File "/home/linyao/.conda/envs/dedalus3/lib/python3.13/site-packages/dedalus/core/solvers.py", line 654, in load_state
    with h5py.File(str(path), mode='r') as file:
         ~~~~~~~~~^^^^^^^^^^^^^^^^^^^^^
  File "/home/linyao/.conda/envs/dedalus3/lib/python3.13/site-packages/h5py/_hl/files.py", line 564, in __init__
    fid = make_fid(name, mode, userblock_size, fapl, fcpl, swmr=swmr)
  File "/home/linyao/.conda/envs/dedalus3/lib/python3.13/site-packages/h5py/_hl/files.py", line 238, in make_fid
    fid = h5f.open(name, flags, fapl=fapl)
  File "h5py/_objects.pyx", line 56, in h5py._objects.with_phil.wrapper
  File "h5py/_objects.pyx", line 57, in h5py._objects.with_phil.wrapper
  File "h5py/h5f.pyx", line 102, in h5py.h5f.open
FileNotFoundError: [Errno 2] Unable to synchronously open file (unable to open file: name = 'snapshots/snapshots_s2.h5', errno = 2, error message = 'No such file or directory', flags = 0, o_flags = 0)
  File "/net/fs06/d0/linyao/GFD_Polar_vortex/ddloutput/NL_findRe/Nphi128_Nr256_Re1.2_F400/ivp.py", line 117, in <module>
    write, initial_timestep = solver.load_state('snapshots/snapshots_s2.h5')
                              ~~~~~~~~~~~~~~~~~^^^^^^^^^^^^^^^^^^^^^^^^^^^^^
  File "/home/linyao/.conda/envs/dedalus3/lib/python3.13/site-packages/dedalus/core/solvers.py", line 654, in load_state
    with h5py.File(str(path), mode='r') as file:
         ~~~~~~~~~^^^^^^^^^^^^^^^^^^^^^
  File "/home/linyao/.conda/envs/dedalus3/lib/python3.13/site-packages/h5py/_hl/files.py", line 564, in __init__
    fid = make_fid(name, mode, userblock_size, fapl, fcpl, swmr=swmr)
  File "/home/linyao/.conda/envs/dedalus3/lib/python3.13/site-packages/h5py/_hl/files.py", line 238, in make_fid
    fid = h5f.open(name, flags, fapl=fapl)
  File "h5py/_objects.pyx", line 56, in h5py._objects.with_phil.wrapper
  File "h5py/_objects.pyx", line 57, in h5py._objects.with_phil.wrapper
  File "h5py/h5f.pyx", line 102, in h5py.h5f.open
FileNotFoundError: [Errno 2] Unable to synchronously open file (unable to open file: name = 'snapshots/snapshots_s2.h5', errno = 2, error message = 'No such file or directory', flags = 0, o_flags = 0)
Traceback (most recent call last):
  File "/net/fs06/d0/linyao/GFD_Polar_vortex/ddloutput/NL_findRe/Nphi128_Nr256_Re1.2_F400/ivp.py", line 117, in <module>
    write, initial_timestep = solver.load_state('snapshots/snapshots_s2.h5')
                              ~~~~~~~~~~~~~~~~~^^^^^^^^^^^^^^^^^^^^^^^^^^^^^
  File "/home/linyao/.conda/envs/dedalus3/lib/python3.13/site-packages/dedalus/core/solvers.py", line 654, in load_state
    with h5py.File(str(path), mode='r') as file:
         ~~~~~~~~~^^^^^^^^^^^^^^^^^^^^^
  File "/home/linyao/.conda/envs/dedalus3/lib/python3.13/site-packages/h5py/_hl/files.py", line 564, in __init__
    fid = make_fid(name, mode, userblock_size, fapl, fcpl, swmr=swmr)
  File "/home/linyao/.conda/envs/dedalus3/lib/python3.13/site-packages/h5py/_hl/files.py", line 238, in make_fid
    fid = h5f.open(name, flags, fapl=fapl)
  File "h5py/_objects.pyx", line 56, in h5py._objects.with_phil.wrapper
  File "h5py/_objects.pyx", line 57, in h5py._objects.with_phil.wrapper
  File "h5py/h5f.pyx", line 102, in h5py.h5f.open
FileNotFoundError: [Errno 2] Unable to synchronously open file (unable to open file: name = 'snapshots/snapshots_s2.h5', errno = 2, error message = 'No such file or directory', flags = 0, o_flags = 0)
